time is:- 2023-08-28 10:49:42.122052-04:00
trying to login
2023-08-28 10:49:42.233675-04:00  :  connected 
['BUY', 'SELL']
TOP_OPT_IMP_VOLAT_GAIN 5 BUY
scanning market
50
TOP_OPEN_PERC_LOSE 5 SELL
scanning market
Error 162, reqId 3: Historical Market Data Service error message:API scanner subscription cancelled: 3
50
{'VFS': 'SELL', 'KMX': 'BUY', 'ATVI': 'BUY', 'FRHC': 'BUY', 'NKE': 'BUY', 'ABT': 'SELL', 'MMM': 'SELL', 'NVDA': 'SELL', 'AMD': 'SELL'}
Traceback (most recent call last):
  File "f:\fintech\dinesh\main.py", line 149, in <module>
    main_process(ibkr)
  File "f:\fintech\dinesh\main.py", line 57, in main_process
    results = list(executor.map(process_symbols_batch, symbols_batches))
  File "C:\Program Files\Python310\lib\concurrent\futures\process.py", line 570, in _chain_from_iterable_of_lists
    for element in iterable:
  File "C:\Program Files\Python310\lib\concurrent\futures\_base.py", line 621, in result_iterator
    yield _result_or_cancel(fs.pop())
  File "C:\Program Files\Python310\lib\concurrent\futures\_base.py", line 319, in _result_or_cancel
    return fut.result(timeout)
  File "C:\Program Files\Python310\lib\concurrent\futures\_base.py", line 458, in result
    return self.__get_result()
  File "C:\Program Files\Python310\lib\concurrent\futures\_base.py", line 403, in __get_result
    raise self._exception
concurrent.futures.process.BrokenProcessPool: A process in the process pool was terminated abruptly while the future was running or pending.
Exception ignored in: <helpers.log.logger.<locals>.Tee object at 0x000001E52109B490>
AttributeError: 'Tee' object has no attribute 'flush'
Exception ignored in sys.unraisablehook: <built-in function unraisablehook>
AttributeError: 'Tee' object has no attribute 'flush'
